Workbook
Name \a: #REF!
Name aa: #REF!
Name asdf: #REF!
Name asdfasfd: #REF!
Name b: #REF!
Name BTV11_15: '[1]arbejds ark LARGE New'!$K$33
Name bvcxx: #REF!
Name bvcxxx: #REF!
Name BVT17_15: '[1]arbejds ark LARGE New'!$S$67
Name d: #REF!
Name ddd: #REF!
Name ddddd: #REF!
Name e: #REF!
Name Elpriser: #REF!
Name EUR__DKK: [2]KeyNH3!$D$34
Name EUR16tilEUR15: '[1]22 Photovoltaics LARGE Old'!$N$2
Name EUR2DKK: #REF!
Name eurusd_rate: [3]Input!$B$7
Name ewr: #REF!
Name f: #REF!
Name fds: #REF!
Name h: #REF!
Name Location: [4]ProjectData!$O$21:$O$74
Name qwer: #REF!
Name sadf: #REF!
Name Sheet: [5]Index!#REF!
Name sheet18: '[6]421 co2 pipeline'!$C$2
Name sheet19: '[6]422 co2 road transport'!$C$2
Name sheet2: #REF!
Name sheet20: '[6]423 co2 ship transport'!$C$2
Name sheet21: '[6]co2 terminals'!$C$2
Name Start10: #REF!
Name Start11: '[5]181 Vanadium Redox Flow Battery'!#REF!
Name Start12: #REF!
Name Start13: #REF!
Name Start14: #REF!
Name Start15: #REF!
Name Start16: #REF!
Name Start17: #REF!
Name Start18: #REF!
Name Start19: #REF!
Name Start2: '[5]140 PTES seasonal'!#REF!
Name Start20: #REF!
Name Start21: #REF!
Name Start22: #REF!
Name Start23: #REF!
Name Start24: #REF!
Name Start25: #REF!
Name Start26: #REF!
Name Start27: #REF!
Name Start28: #REF!
Name Start29: #REF!
Name Start3: '[7]141 Large hot water tank'!#REF!
Name Start30: #REF!
Name Start31: #REF!
Name Start32: #REF!
Name Start33: #REF!
Name Start34: #REF!
Name Start35: #REF!
Name Start36: #REF!

Sheet ★Unit Cost Projection
A1: Moon et al., 2025
A2: NREL 2023 data | C2: Future Cost = Base Cost × (1 + CAGR)^(Target Year - Base Year)
A3: DEA | K3: 11차 전기본과 sync
B4: Technology | C4: 2025 | G4: 2030 | K4: 2038 | O4: 2040 | S4: 2050
C5: CAPEX/ MCI (원/kW) | D5: Fixed O&M (FOM) (원/kW/yr) | E5: Variable O&M (VOM) (원/kWh) | F5: Fuel Cost (원/kWh) | G5: CAPEX/ MCI (원/kW) | H5: Fixed O&M (FOM) (원/kW/yr) | I5: Variable O&M (VOM) (원/kWh) | J5: Fuel Cost (원/kWh) | K5: CAPEX/ MCI (원/kW) | L5: Fixed O&M (FOM) (원/kW/yr) | M5: Variable O&M (VOM) (원/kWh) | N5: Fuel Cost (원/kWh) | O5: CAPEX/ MCI (원/kW) | P5: Fixed O&M (FOM) (원/kW/yr) | Q5: Variable O&M (VOM) (원/kWh) | R5: Fuel Cost (원/kWh) | S5: CAPEX/ MCI (원/kW) | T5: Fixed O&M (FOM) (원/kW/yr) | U5: Variable O&M (VOM) (원/kWh) | V5: Fuel Cost (원/kWh)
A6: Renewable | B6: Solar PV(< 100MW) | C6: ='[7]★Cost datasheet_v2'!E6*(1+'[7]★Cost datasheet_v2'!O6)^(2025-'[7]★Cost datasheet_v2'!$D6) -> 1374397.9 | D6: ='[7]★Cost datasheet_v2'!F6*(1+'[7]★Cost datasheet_v2'!P6)^(2025-'[7]★Cost datasheet_v2'!$D6) -> 33670.306 | E6: ='[7]★Cost datasheet_v2'!G6*(1+'[7]★Cost datasheet_v2'!Q6)^(2025-'[7]★Cost datasheet_v2'!$D6) -> #REF! | F6: ='[7]★Cost datasheet_v2'!H6*(1+'[7]★Cost datasheet_v2'!R6)^(2025-'[7]★Cost datasheet_v2'!$D6) -> #REF! | G6: ='[7]★Cost datasheet_v2'!E6*(1+'[7]★Cost datasheet_v2'!O6)^(2030-'[7]★Cost datasheet_v2'!$D6) -> 1192460 | H6: ='[7]★Cost datasheet_v2'!F6*(1+'[7]★Cost datasheet_v2'!P6)^(2030-'[7]★Cost datasheet_v2'!$D6) -> 29849.06 | I6: ='[7]★Cost datasheet_v2'!G6*(1+'[7]★Cost datasheet_v2'!Q6)^(2030-'[7]★Cost datasheet_v2'!$D6) -> #REF! | J6: ='[7]★Cost datasheet_v2'!H6*(1+'[7]★Cost datasheet_v2'!R6)^(2030-'[7]★Cost datasheet_v2'!$D6) -> #REF! | K6: ='[7]★Cost datasheet_v2'!E6*(1+'[7]★Cost datasheet_v2'!O6)^(2038-'[7]★Cost datasheet_v2'!$D6) -> 950110.1 | L6: ='[7]★Cost datasheet_v2'!F6*(1+'[7]★Cost datasheet_v2'!P6)^(2038-'[7]★Cost datasheet_v2'!$D6) -> 24616.393 | M6: ='[7]★Cost datasheet_v2'!G6*(1+'[7]★Cost datasheet_v2'!Q6)^(2038-'[7]★Cost datasheet_v2'!$D6) -> #REF! | N6: ='[7]★Cost datasheet_v2'!H6*(1+'[7]★Cost datasheet_v2'!R6)^(2038-'[7]★Cost datasheet_v2'!$D6) -> #REF! | O6: ='[7]★Cost datasheet_v2'!E6*(1+'[7]★Cost datasheet_v2'!O6)^(2040-'[7]★Cost datasheet_v2'!$D6) -> 897648.82 | P6: ='[7]★Cost datasheet_v2'!F6*(1+'[7]★Cost datasheet_v2'!P6)^(2040-'[7]★Cost datasheet_v2'!$D6) -> 23458.371 | Q6: ='[7]★Cost datasheet_v2'!G6*(1+'[7]★Cost datasheet_v2'!Q6)^(2040-'[7]★Cost datasheet_v2'!$D6) -> #REF! | R6: ='[7]★Cost datasheet_v2'!H6*(1+'[7]★Cost datasheet_v2'!R6)^(2040-'[7]★Cost datasheet_v2'!$D6) -> #REF! | S6: ='[7]★Cost datasheet_v2'!E6*(1+'[7]★Cost datasheet_v2'!O6)^(2050-'[7]★Cost datasheet_v2'!$D6) -> 675723.64 | T6: ='[7]★Cost datasheet_v2'!F6*(1+'[7]★Cost datasheet_v2'!P6)^(2050-'[7]★Cost datasheet_v2'!$D6) -> 18435.929 | U6: ='[7]★Cost datasheet_v2'!G6*(1+'[7]★Cost datasheet_v2'!Q6)^(2050-'[7]★Cost datasheet_v2'!$D6) -> #REF! | V6: ='[7]★Cost datasheet_v2'!H6*(1+'[7]★Cost datasheet_v2'!R6)^(2050-'[7]★Cost datasheet_v2'!$D6) -> #REF!
B7: Solar PV(> 100MW) | C7: ='[7]★Cost datasheet_v2'!E7*(1+'[7]★Cost datasheet_v2'!O7)^(2025-'[7]★Cost datasheet_v2'!$D7) -> 1183348.6 | D7: ='[7]★Cost datasheet_v2'!F7*(1+'[7]★Cost datasheet_v2'!P7)^(2025-'[7]★Cost datasheet_v2'!$D7) -> 29232.527 | E7: ='[7]★Cost datasheet_v2'!G7*(1+'[7]★Cost datasheet_v2'!Q7)^(2025-'[7]★Cost datasheet_v2'!$D7) -> #REF! | F7: ='[7]★Cost datasheet_v2'!H7*(1+'[7]★Cost datasheet_v2'!R7)^(2025-'[7]★Cost datasheet_v2'!$D7) -> #REF! | G7: ='[7]★Cost datasheet_v2'!E7*(1+'[7]★Cost datasheet_v2'!O7)^(2030-'[7]★Cost datasheet_v2'!$D7) -> 1026701.1 | H7: ='[7]★Cost datasheet_v2'!F7*(1+'[7]★Cost datasheet_v2'!P7)^(2030-'[7]★Cost datasheet_v2'!$D7) -> 26460.478 | I7: ='[7]★Cost datasheet_v2'!G7*(1+'[7]★Cost datasheet_v2'!Q7)^(2030-'[7]★Cost datasheet_v2'!$D7) -> #REF! | J7: ='[7]★Cost datasheet_v2'!H7*(1+'[7]★Cost datasheet_v2'!R7)^(2030-'[7]★Cost datasheet_v2'!$D7) -> #REF! | K7: ='[7]★Cost datasheet_v2'!E7*(1+'[7]★Cost datasheet_v2'!O7)^(2038-'[7]★Cost datasheet_v2'!$D7) -> 818039.22 | L7: ='[7]★Cost datasheet_v2'!F7*(1+'[7]★Cost datasheet_v2'!P7)^(2038-'[7]★Cost datasheet_v2'!$D7) -> 22561.491 | M7: ='[7]★Cost datasheet_v2'!G7*(1+'[7]★Cost datasheet_v2'!Q7)^(2038-'[7]★Cost datasheet_v2'!$D7) -> #REF! | N7: ='[7]★Cost datasheet_v2'!H7*(1+'[7]★Cost datasheet_v2'!R7)^(2038-'[7]★Cost datasheet_v2'!$D7) -> #REF! | O7: ='[7]★Cost datasheet_v2'!E7*(1+'[7]★Cost datasheet_v2'!O7)^(2040-'[7]★Cost datasheet_v2'!$D7) -> 772870.37 | P7: ='[7]★Cost datasheet_v2'!F7*(1+'[7]★Cost datasheet_v2'!P7)^(2040-'[7]★Cost datasheet_v2'!$D7) -> 21680.053 | Q7: ='[7]★Cost datasheet_v2'!G7*(1+'[7]★Cost datasheet_v2'!Q7)^(2040-'[7]★Cost datasheet_v2'!$D7) -> #REF! | R7: ='[7]★Cost datasheet_v2'!H7*(1+'[7]★Cost datasheet_v2'!R7)^(2040-'[7]★Cost datasheet_v2'!$D7) -> #REF! | S7: ='[7]★Cost datasheet_v2'!E7*(1+'[7]★Cost datasheet_v2'!O7)^(2050-'[7]★Cost datasheet_v2'!$D7) -> 581794.09 | T7: ='[7]★Cost datasheet_v2'!F7*(1+'[7]★Cost datasheet_v2'!P7)^(2050-'[7]★Cost datasheet_v2'!$D7) -> 17763.273 | U7: ='[7]★Cost datasheet_v2'!G7*(1+'[7]★Cost datasheet_v2'!Q7)^(2050-'[7]★Cost datasheet_v2'!$D7) -> #REF! | V7: ='[7]★Cost datasheet_v2'!H7*(1+'[7]★Cost datasheet_v2'!R7)^(2050-'[7]★Cost datasheet_v2'!$D7) -> #REF!
B8: Onshore Wind | C8: ='[7]★Cost datasheet_v2'!E8*(1+'[7]★Cost datasheet_v2'!O8)^(2025-'[7]★Cost datasheet_v2'!$D8) -> 2518972.3 | D8: ='[7]★Cost datasheet_v2'!F8*(1+'[7]★Cost datasheet_v2'!P8)^(2025-'[7]★Cost datasheet_v2'!$D8) -> 54620.699 | E8: ='[7]★Cost datasheet_v2'!G8*(1+'[7]★Cost datasheet_v2'!Q8)^(2025-'[7]★Cost datasheet_v2'!$D8) -> #REF! | F8: ='[7]★Cost datasheet_v2'!H8*(1+'[7]★Cost datasheet_v2'!R8)^(2025-'[7]★Cost datasheet_v2'!$D8) -> #REF! | G8: ='[7]★Cost datasheet_v2'!E8*(1+'[7]★Cost datasheet_v2'!O8)^(2030-'[7]★Cost datasheet_v2'!$D8) -> 2300280.7 | H8: ='[7]★Cost datasheet_v2'!F8*(1+'[7]★Cost datasheet_v2'!P8)^(2030-'[7]★Cost datasheet_v2'!$D8) -> 51217.304 | I8: ='[7]★Cost datasheet_v2'!G8*(1+'[7]★Cost datasheet_v2'!Q8)^(2030-'[7]★Cost datasheet_v2'!$D8) -> #REF! | J8: ='[7]★Cost datasheet_v2'!H8*(1+'[7]★Cost datasheet_v2'!R8)^(2030-'[7]★Cost datasheet_v2'!$D8) -> #REF! | K8: ='[7]★Cost datasheet_v2'!E8*(1+'[7]★Cost datasheet_v2'!O8)^(2038-'[7]★Cost datasheet_v2'!$D8) -> 1989173.8 | L8: ='[7]★Cost datasheet_v2'!F8*(1+'[7]★Cost datasheet_v2'!P8)^(2038-'[7]★Cost datasheet_v2'!$D8) -> 46207.435 | M8: ='[7]★Cost datasheet_v2'!G8*(1+'[7]★Cost datasheet_v2'!Q8)^(2038-'[7]★Cost datasheet_v2'!$D8) -> #REF! | N8: ='[7]★Cost datasheet_v2'!H8*(1+'[7]★Cost datasheet_v2'!R8)^(2038-'[7]★Cost datasheet_v2'!$D8) -> #REF! | O8: ='[7]★Cost datasheet_v2'!E8*(1+'[7]★Cost datasheet_v2'!O8)^(2040-'[7]★Cost datasheet_v2'!$D8) -> 1918208 | P8: ='[7]★Cost datasheet_v2'!F8*(1+'[7]★Cost datasheet_v2'!P8)^(2040-'[7]★Cost datasheet_v2'!$D8) -> 45033.495 | Q8: ='[7]★Cost datasheet_v2'!G8*(1+'[7]★Cost datasheet_v2'!Q8)^(2040-'[7]★Cost datasheet_v2'!$D8) -> #REF! | R8: ='[7]★Cost datasheet_v2'!H8*(1+'[7]★Cost datasheet_v2'!R8)^(2040-'[7]★Cost datasheet_v2'!$D8) -> #REF! | S8: ='[7]★Cost datasheet_v2'!E8*(1+'[7]★Cost datasheet_v2'!O8)^(2050-'[7]★Cost datasheet_v2'!$D8) -> 1599597 | T8: ='[7]★Cost datasheet_v2'!F8*(1+'[7]★Cost datasheet_v2'!P8)^(2050-'[7]★Cost datasheet_v2'!$D8) -> 39596.298 | U8: ='[7]★Cost datasheet_v2'!G8*(1+'[7]★Cost datasheet_v2'!Q8)^(2050-'[7]★Cost datasheet_v2'!$D8) -> #REF! | V8: ='[7]★Cost datasheet_v2'!H8*(1+'[7]★Cost datasheet_v2'!R8)^(2050-'[7]★Cost datasheet_v2'!$D8) -> #REF!
B9: Offshore Wind (Fixed) | C9: ='[7]★Cost datasheet_v2'!E9*(1+'[7]★Cost datasheet_v2'!O9)^(2025-'[7]★Cost datasheet_v2'!$D9) -> 6222998.7 | D9: ='[7]★Cost datasheet_v2'!F9*(1+'[7]★Cost datasheet_v2'!P9)^(2025-'[7]★Cost datasheet_v2'!$D9) -> 125975.2 | E9: ='[7]★Cost datasheet_v2'!G9*(1+'[7]★Cost datasheet_v2'!Q9)^(2025-'[7]★Cost datasheet_v2'!$D9) -> #REF! | F9: ='[7]★Cost datasheet_v2'!H9*(1+'[7]★Cost datasheet_v2'!R9)^(2025-'[7]★Cost datasheet_v2'!$D9) -> #REF! | G9: ='[7]★Cost datasheet_v2'!E9*(1+'[7]★Cost datasheet_v2'!O9)^(2030-'[7]★Cost datasheet_v2'!$D9) -> 5539525 | H9: ='[7]★Cost datasheet_v2'!F9*(1+'[7]★Cost datasheet_v2'!P9)^(2030-'[7]★Cost datasheet_v2'!$D9) -> 121223.11 | I9: ='[7]★Cost datasheet_v2'!G9*(1+'[7]★Cost datasheet_v2'!Q9)^(2030-'[7]★Cost datasheet_v2'!$D9) -> #REF! | J9: ='[7]★Cost datasheet_v2'!H9*(1+'[7]★Cost datasheet_v2'!R9)^(2030-'[7]★Cost datasheet_v2'!$D9) -> #REF! | K9: ='[7]★Cost datasheet_v2'!E9*(1+'[7]★Cost datasheet_v2'!O9)^(2038-'[7]★Cost datasheet_v2'!$D9) -> 4598636 | L9: ='[7]★Cost datasheet_v2'!F9*(1+'[7]★Cost datasheet_v2'!P9)^(2038-'[7]★Cost datasheet_v2'!$D9) -> 113989.8 | M9: ='[7]★Cost datasheet_v2'!G9*(1+'[7]★Cost datasheet_v2'!Q9)^(2038-'[7]★Cost datasheet_v2'!$D9) -> #REF! | N9: ='[7]★Cost datasheet_v2'!H9*(1+'[7]★Cost datasheet_v2'!R9)^(2038-'[7]★Cost datasheet_v2'!$D9) -> #REF! | O9: ='[7]★Cost datasheet_v2'!E9*(1+'[7]★Cost datasheet_v2'!O9)^(2040-'[7]★Cost datasheet_v2'!$D9) -> 4389531.5 | P9: ='[7]★Cost datasheet_v2'!F9*(1+'[7]★Cost datasheet_v2'!P9)^(2040-'[7]★Cost datasheet_v2'!$D9) -> 112249.94 | Q9: ='[7]★Cost datasheet_v2'!G9*(1+'[7]★Cost datasheet_v2'!Q9)^(2040-'[7]★Cost datasheet_v2'!$D9) -> #REF! | R9: ='[7]★Cost datasheet_v2'!H9*(1+'[7]★Cost datasheet_v2'!R9)^(2040-'[7]★Cost datasheet_v2'!$D9) -> #REF! | S9: ='[7]★Cost datasheet_v2'!E9*(1+'[7]★Cost datasheet_v2'!O9)^(2050-'[7]★Cost datasheet_v2'!$D9) -> 3478274.1 | T9: ='[7]★Cost datasheet_v2'!F9*(1+'[7]★Cost datasheet_v2'!P9)^(2050-'[7]★Cost datasheet_v2'!$D9) -> 103940.98 | U9: ='[7]★Cost datasheet_v2'!G9*(1+'[7]★Cost datasheet_v2'!Q9)^(2050-'[7]★Cost datasheet_v2'!$D9) -> #REF! | V9: ='[7]★Cost datasheet_v2'!H9*(1+'[7]★Cost datasheet_v2'!R9)^(2050-'[7]★Cost datasheet_v2'!$D9) -> #REF!
B10: Offshore Wind (Floating) | C10: ='[7]★Cost datasheet_v2'!E10*(1+'[7]★Cost datasheet_v2'!O10)^(2025-'[7]★Cost datasheet_v2'!$D10) -> 9166544 | D10: ='[7]★Cost datasheet_v2'!F10*(1+'[7]★Cost datasheet_v2'!P10)^(2025-'[7]★Cost datasheet_v2'!$D10) -> 126000.02 | E10: ='[7]★Cost datasheet_v2'!G10*(1+'[7]★Cost datasheet_v2'!Q10)^(2025-'[7]★Cost datasheet_v2'!$D10) -> #REF! | F10: ='[7]★Cost datasheet_v2'!H10*(1+'[7]★Cost datasheet_v2'!R10)^(2025-'[7]★Cost datasheet_v2'!$D10) -> #REF! | G10: ='[7]★Cost datasheet_v2'!E10*(1+'[7]★Cost datasheet_v2'!O10)^(2030-'[7]★Cost datasheet_v2'!$D10) -> 8201624.9 | H10: ='[7]★Cost datasheet_v2'!F10*(1+'[7]★Cost datasheet_v2'!P10)^(2030-'[7]★Cost datasheet_v2'!$D10) -> 121306.72 | I10: ='[7]★Cost datasheet_v2'!G10*(1+'[7]★Cost datasheet_v2'!Q10)^(2030-'[7]★Cost datasheet_v2'!$D10) -> #REF! | J10: ='[7]★Cost datasheet_v2'!H10*(1+'[7]★Cost datasheet_v2'!R10)^(2030-'[7]★Cost datasheet_v2'!$D10) -> #REF! | K10: ='[7]★Cost datasheet_v2'!E10*(1+'[7]★Cost datasheet_v2'!O10)^(2038-'[7]★Cost datasheet_v2'!$D10) -> 6864528.9 | L10: ='[7]★Cost datasheet_v2'!F10*(1+'[7]★Cost datasheet_v2'!P10)^(2038-'[7]★Cost datasheet_v2'!$D10) -> 114158.34 | M10: ='[7]★Cost datasheet_v2'!G10*(1+'[7]★Cost datasheet_v2'!Q10)^(2038-'[7]★Cost datasheet_v2'!$D10) -> #REF! | N10: ='[7]★Cost datasheet_v2'!H10*(1+'[7]★Cost datasheet_v2'!R10)^(2038-'[7]★Cost datasheet_v2'!$D10) -> #REF! | O10: ='[7]★Cost datasheet_v2'!E10*(1+'[7]★Cost datasheet_v2'!O10)^(2040-'[7]★Cost datasheet_v2'!$D10) -> 6565812.1 | P10: ='[7]★Cost datasheet_v2'!F10*(1+'[7]★Cost datasheet_v2'!P10)^(2040-'[7]★Cost datasheet_v2'!$D10) -> 112438.06 | Q10: ='[7]★Cost datasheet_v2'!G10*(1+'[7]★Cost datasheet_v2'!Q10)^(2040-'[7]★Cost datasheet_v2'!$D10) -> #REF! | R10: ='[7]★Cost datasheet_v2'!H10*(1+'[7]★Cost datasheet_v2'!R10)^(2040-'[7]★Cost datasheet_v2'!$D10) -> #REF! | S10: ='[7]★Cost datasheet_v2'!E10*(1+'[7]★Cost datasheet_v2'!O10)^(2050-'[7]★Cost datasheet_v2'!$D10) -> 5256261.9 | T10: ='[7]★Cost datasheet_v2'!F10*(1+'[7]★Cost datasheet_v2'!P10)^(2050-'[7]★Cost datasheet_v2'!$D10) -> 104217.78 | U10: ='[7]★Cost datasheet_v2'!G10*(1+'[7]★Cost datasheet_v2'!Q10)^(2050-'[7]★Cost datasheet_v2'!$D10) -> #REF! | V10: ='[7]★Cost datasheet_v2'!H10*(1+'[7]★Cost datasheet_v2'!R10)^(2050-'[7]★Cost datasheet_v2'!$D10) -> #REF!
B11: Pumped Storage Hydropower | C11: ='[7]★Cost datasheet_v2'!E11*(1+'[7]★Cost datasheet_v2'!O11)^(2025-'[7]★Cost datasheet_v2'!$D11) -> 2523845.2 | D11: ='[7]★Cost datasheet_v2'!F11*(1+'[7]★Cost datasheet_v2'!P11)^(2025-'[7]★Cost datasheet_v2'!$D11) -> 24610.872 | E11: ='[7]★Cost datasheet_v2'!G11*(1+'[7]★Cost datasheet_v2'!Q11)^(2025-'[7]★Cost datasheet_v2'!$D11) -> 706.6488 | F11: ='[7]★Cost datasheet_v2'!H11*(1+'[7]★Cost datasheet_v2'!R11)^(2025-'[7]★Cost datasheet_v2'!$D11) -> #REF! | G11: ='[7]★Cost datasheet_v2'!E11*(1+'[7]★Cost datasheet_v2'!O11)^(2030-'[7]★Cost datasheet_v2'!$D11) -> 2523845.2 | H11: ='[7]★Cost datasheet_v2'!F11*(1+'[7]★Cost datasheet_v2'!P11)^(2030-'[7]★Cost datasheet_v2'!$D11) -> 24610.872 | I11: ='[7]★Cost datasheet_v2'!G11*(1+'[7]★Cost datasheet_v2'!Q11)^(2030-'[7]★Cost datasheet_v2'!$D11) -> 706.6488 | J11: ='[7]★Cost datasheet_v2'!H11*(1+'[7]★Cost datasheet_v2'!R11)^(2030-'[7]★Cost datasheet_v2'!$D11) -> #REF! | K11: ='[7]★Cost datasheet_v2'!E11*(1+'[7]★Cost datasheet_v2'!O11)^(2038-'[7]★Cost datasheet_v2'!$D11) -> 2523845.2 | L11: ='[7]★Cost datasheet_v2'!F11*(1+'[7]★Cost datasheet_v2'!P11)^(2038-'[7]★Cost datasheet_v2'!$D11) -> 24610.872 | M11: ='[7]★Cost datasheet_v2'!G11*(1+'[7]★Cost datasheet_v2'!Q11)^(2038-'[7]★Cost datasheet_v2'!$D11) -> 706.6488 | N11: ='[7]★Cost datasheet_v2'!H11*(1+'[7]★Cost datasheet_v2'!R11)^(2038-'[7]★Cost datasheet_v2'!$D11) -> #REF! | O11: ='[7]★Cost datasheet_v2'!E11*(1+'[7]★Cost datasheet_v2'!O11)^(2040-'[7]★Cost datasheet_v2'!$D11) -> 2523845.2 | P11: ='[7]★Cost datasheet_v2'!F11*(1+'[7]★Cost datasheet_v2'!P11)^(2040-'[7]★Cost datasheet_v2'!$D11) -> 24610.872 | Q11: ='[7]★Cost datasheet_v2'!G11*(1+'[7]★Cost datasheet_v2'!Q11)^(2040-'[7]★Cost datasheet_v2'!$D11) -> 706.6488 | R11: ='[7]★Cost datasheet_v2'!H11*(1+'[7]★Cost datasheet_v2'!R11)^(2040-'[7]★Cost datasheet_v2'!$D11) -> #REF! | S11: ='[7]★Cost datasheet_v2'!E11*(1+'[7]★Cost datasheet_v2'!O11)^(2050-'[7]★Cost datasheet_v2'!$D11) -> 2523845.2 | T11: ='[7]★Cost datasheet_v2'!F11*(1+'[7]★Cost datasheet_v2'!P11)^(2050-'[7]★Cost datasheet_v2'!$D11) -> 24610.872 | U11: ='[7]★Cost datasheet_v2'!G11*(1+'[7]★Cost datasheet_v2'!Q11)^(2050-'[7]★Cost datasheet_v2'!$D11) -> 706.6488 | V11: ='[7]★Cost datasheet_v2'!H11*(1+'[7]★Cost datasheet_v2'!R11)^(2050-'[7]★Cost datasheet_v2'!$D11) -> #REF!
B12: Hydrogen Turbine | C12: ='[7]★Cost datasheet_v2'!E12*(1+'[7]★Cost datasheet_v2'!O12)^(2025-'[7]★Cost datasheet_v2'!$D12) -> #REF! | D12: ='[7]★Cost datasheet_v2'!F12*(1+'[7]★Cost datasheet_v2'!P12)^(2025-'[7]★Cost datasheet_v2'!$D12) -> #REF! | E12: ='[7]★Cost datasheet_v2'!G12*(1+'[7]★Cost datasheet_v2'!Q12)^(2025-'[7]★Cost datasheet_v2'!$D12) -> #REF! | F12: ='[7]★Cost datasheet_v2'!H12*(1+'[7]★Cost datasheet_v2'!R12)^(2025-'[7]★Cost datasheet_v2'!$D12) -> #REF! | G12: ='[7]★Cost datasheet_v2'!E12*(1+'[7]★Cost datasheet_v2'!O12)^(2030-'[7]★Cost datasheet_v2'!$D12) -> #REF! | H12: ='[7]★Cost datasheet_v2'!F12*(1+'[7]★Cost datasheet_v2'!P12)^(2030-'[7]★Cost datasheet_v2'!$D12) -> #REF! | I12: ='[7]★Cost datasheet_v2'!G12*(1+'[7]★Cost datasheet_v2'!Q12)^(2030-'[7]★Cost datasheet_v2'!$D12) -> #REF! | J12: ='[7]★Cost datasheet_v2'!H12*(1+'[7]★Cost datasheet_v2'!R12)^(2030-'[7]★Cost datasheet_v2'!$D12) -> #REF! | K12: ='[7]★Cost datasheet_v2'!E12*(1+'[7]★Cost datasheet_v2'!O12)^(2038-'[7]★Cost datasheet_v2'!$D12) -> #REF! | L12: ='[7]★Cost datasheet_v2'!F12*(1+'[7]★Cost datasheet_v2'!P12)^(2038-'[7]★Cost datasheet_v2'!$D12) -> #REF! | M12: ='[7]★Cost datasheet_v2'!G12*(1+'[7]★Cost datasheet_v2'!Q12)^(2038-'[7]★Cost datasheet_v2'!$D12) -> #REF! | N12: ='[7]★Cost datasheet_v2'!H12*(1+'[7]★Cost datasheet_v2'!R12)^(2038-'[7]★Cost datasheet_v2'!$D12) -> #REF! | O12: ='[7]★Cost datasheet_v2'!E12*(1+'[7]★Cost datasheet_v2'!O12)^(2040-'[7]★Cost datasheet_v2'!$D12) -> #REF! | P12: ='[7]★Cost datasheet_v2'!F12*(1+'[7]★Cost datasheet_v2'!P12)^(2040-'[7]★Cost datasheet_v2'!$D12) -> #REF! | Q12: ='[7]★Cost datasheet_v2'!G12*(1+'[7]★Cost datasheet_v2'!Q12)^(2040-'[7]★Cost datasheet_v2'!$D12) -> #REF! | R12: ='[7]★Cost datasheet_v2'!H12*(1+'[7]★Cost datasheet_v2'!R12)^(2040-'[7]★Cost datasheet_v2'!$D12) -> #REF! | S12: ='[7]★Cost datasheet_v2'!E12*(1+'[7]★Cost datasheet_v2'!O12)^(2050-'[7]★Cost datasheet_v2'!$D12) -> #REF! | T12: ='[7]★Cost datasheet_v2'!F12*(1+'[7]★Cost datasheet_v2'!P12)^(2050-'[7]★Cost datasheet_v2'!$D12) -> #REF! | U12: ='[7]★Cost datasheet_v2'!G12*(1+'[7]★Cost datasheet_v2'!Q12)^(2050-'[7]★Cost datasheet_v2'!$D12) -> #REF! | V12: ='[7]★Cost datasheet_v2'!H12*(1+'[7]★Cost datasheet_v2'!R12)^(2050-'[7]★Cost datasheet_v2'!$D12) -> #REF!
A14: Conventional | B14: Coal (유연탄) | C14: ='[7]★Cost datasheet_v2'!E14*(1+'[7]★Cost datasheet_v2'!O14)^(2025-'[7]★Cost datasheet_v2'!$D14) -> 2276001.7 | D14: ='[7]★Cost datasheet_v2'!F14*(1+'[7]★Cost datasheet_v2'!P14)^(2025-'[7]★Cost datasheet_v2'!$D14) -> 79295.165 | E14: ='[7]★Cost datasheet_v2'!G14*(1+'[7]★Cost datasheet_v2'!Q14)^(2025-'[7]★Cost datasheet_v2'!$D14) -> 11194.44 | F14: ='[7]★Cost datasheet_v2'!H14*(1+'[7]★Cost datasheet_v2'!R14)^(2025-'[7]★Cost datasheet_v2'!$D14) -> 78938.384 | G14: ='[7]★Cost datasheet_v2'!E14*(1+'[7]★Cost datasheet_v2'!O14)^(2030-'[7]★Cost datasheet_v2'!$D14) -> 2466428.5 | H14: ='[7]★Cost datasheet_v2'!F14*(1+'[7]★Cost datasheet_v2'!P14)^(2030-'[7]★Cost datasheet_v2'!$D14) -> 76571.043 | I14: ='[7]★Cost datasheet_v2'!G14*(1+'[7]★Cost datasheet_v2'!Q14)^(2030-'[7]★Cost datasheet_v2'!$D14) -> 10978.468 | J14: ='[7]★Cost datasheet_v2'!H14*(1+'[7]★Cost datasheet_v2'!R14)^(2030-'[7]★Cost datasheet_v2'!$D14) -> 62794.826 | K14: ='[7]★Cost datasheet_v2'!E14*(1+'[7]★Cost datasheet_v2'!O14)^(2038-'[7]★Cost datasheet_v2'!$D14) -> 2804801 | L14: ='[7]★Cost datasheet_v2'!F14*(1+'[7]★Cost datasheet_v2'!P14)^(2038-'[7]★Cost datasheet_v2'!$D14) -> 72405.762 | M14: ='[7]★Cost datasheet_v2'!G14*(1+'[7]★Cost datasheet_v2'!Q14)^(2038-'[7]★Cost datasheet_v2'!$D14) -> 10641.547 | N14: ='[7]★Cost datasheet_v2'!H14*(1+'[7]★Cost datasheet_v2'!R14)^(2038-'[7]★Cost datasheet_v2'!$D14) -> 43545.258 | O14: ='[7]★Cost datasheet_v2'!E14*(1+'[7]★Cost datasheet_v2'!O14)^(2040-'[7]★Cost datasheet_v2'!$D14) -> 2896412.7 | P14: ='[7]★Cost datasheet_v2'!F14*(1+'[7]★Cost datasheet_v2'!P14)^(2040-'[7]★Cost datasheet_v2'!$D14) -> 71400.339 | Q14: ='[7]★Cost datasheet_v2'!G14*(1+'[7]★Cost datasheet_v2'!Q14)^(2040-'[7]★Cost datasheet_v2'!$D14) -> 10558.945 | R14: ='[7]★Cost datasheet_v2'!H14*(1+'[7]★Cost datasheet_v2'!R14)^(2040-'[7]★Cost datasheet_v2'!$D14) -> 39737.004 | S14: ='[7]★Cost datasheet_v2'!E14*(1+'[7]★Cost datasheet_v2'!O14)^(2050-'[7]★Cost datasheet_v2'!$D14) -> 3401358 | T14: ='[7]★Cost datasheet_v2'!F14*(1+'[7]★Cost datasheet_v2'!P14)^(2050-'[7]★Cost datasheet_v2'!$D14) -> 66578.803 | U14: ='[7]★Cost datasheet_v2'!G14*(1+'[7]★Cost datasheet_v2'!Q14)^(2050-'[7]★Cost datasheet_v2'!$D14) -> 10155.452 | V14: ='[7]★Cost datasheet_v2'!H14*(1+'[7]★Cost datasheet_v2'!R14)^(2050-'[7]★Cost datasheet_v2'!$D14) -> 25145.853
B15: LNG | C15: ='[7]★Cost datasheet_v2'!E15*(1+'[7]★Cost datasheet_v2'!O15)^(2025-'[7]★Cost datasheet_v2'!$D15) -> 1604147.1 | D15: ='[7]★Cost datasheet_v2'!F15*(1+'[7]★Cost datasheet_v2'!P15)^(2025-'[7]★Cost datasheet_v2'!$D15) -> 50294.726 | E15: ='[7]★Cost datasheet_v2'!G15*(1+'[7]★Cost datasheet_v2'!Q15)^(2025-'[7]★Cost datasheet_v2'!$D15) -> 2584.6481 | F15: ='[7]★Cost datasheet_v2'!H15*(1+'[7]★Cost datasheet_v2'!R15)^(2025-'[7]★Cost datasheet_v2'!$D15) -> 213174.2 | G15: ='[7]★Cost datasheet_v2'!E15*(1+'[7]★Cost datasheet_v2'!O15)^(2030-'[7]★Cost datasheet_v2'!$D15) -> 1738361.7 | H15: ='[7]★Cost datasheet_v2'!F15*(1+'[7]★Cost datasheet_v2'!P15)^(2030-'[7]★Cost datasheet_v2'!$D15) -> 48168.847 | I15: ='[7]★Cost datasheet_v2'!G15*(1+'[7]★Cost datasheet_v2'!Q15)^(2030-'[7]★Cost datasheet_v2'!$D15) -> 2499.5957 | J15: ='[7]★Cost datasheet_v2'!H15*(1+'[7]★Cost datasheet_v2'!R15)^(2030-'[7]★Cost datasheet_v2'!$D15) -> 131914.5 | K15: ='[7]★Cost datasheet_v2'!E15*(1+'[7]★Cost datasheet_v2'!O15)^(2038-'[7]★Cost datasheet_v2'!$D15) -> 1976849.8 | L15: ='[7]★Cost datasheet_v2'!F15*(1+'[7]★Cost datasheet_v2'!P15)^(2038-'[7]★Cost datasheet_v2'!$D15) -> 44952.759 | M15: ='[7]★Cost datasheet_v2'!G15*(1+'[7]★Cost datasheet_v2'!Q15)^(2038-'[7]★Cost datasheet_v2'!$D15) -> 2369.2949 | N15: ='[7]★Cost datasheet_v2'!H15*(1+'[7]★Cost datasheet_v2'!R15)^(2038-'[7]★Cost datasheet_v2'!$D15) -> 61204.756 | O15: ='[7]★Cost datasheet_v2'!E15*(1+'[7]★Cost datasheet_v2'!O15)^(2040-'[7]★Cost datasheet_v2'!$D15) -> 2041418.5 | P15: ='[7]★Cost datasheet_v2'!F15*(1+'[7]★Cost datasheet_v2'!P15)^(2040-'[7]★Cost datasheet_v2'!$D15) -> 44182.865 | Q15: ='[7]★Cost datasheet_v2'!G15*(1+'[7]★Cost datasheet_v2'!Q15)^(2040-'[7]★Cost datasheet_v2'!$D15) -> 2337.7952 | R15: ='[7]★Cost datasheet_v2'!H15*(1+'[7]★Cost datasheet_v2'!R15)^(2040-'[7]★Cost datasheet_v2'!$D15) -> 50513.601 | S15: ='[7]★Cost datasheet_v2'!E15*(1+'[7]★Cost datasheet_v2'!O15)^(2050-'[7]★Cost datasheet_v2'!$D15) -> 2397308.7 | T15: ='[7]★Cost datasheet_v2'!F15*(1+'[7]★Cost datasheet_v2'!P15)^(2050-'[7]★Cost datasheet_v2'!$D15) -> 40526.723 | U15: ='[7]★Cost datasheet_v2'!G15*(1+'[7]★Cost datasheet_v2'!Q15)^(2050-'[7]★Cost datasheet_v2'!$D15) -> 2186.4682 | V15: ='[7]★Cost datasheet_v2'!H15*(1+'[7]★Cost datasheet_v2'!R15)^(2050-'[7]★Cost datasheet_v2'!$D15) -> 19343.012
B16: Nuclear | C16: ='[7]★Cost datasheet_v2'!E16*(1+'[7]★Cost datasheet_v2'!O16)^(2025-'[7]★Cost datasheet_v2'!$D16) -> 5441632.7 | D16: ='[7]★Cost datasheet_v2'!F16*(1+'[7]★Cost datasheet_v2'!P16)^(2025-'[7]★Cost datasheet_v2'!$D16) -> 169352.04 | E16: ='[7]★Cost datasheet_v2'!G16*(1+'[7]★Cost datasheet_v2'!Q16)^(2025-'[7]★Cost datasheet_v2'!$D16) -> #REF! | F16: ='[7]★Cost datasheet_v2'!H16*(1+'[7]★Cost datasheet_v2'!R16)^(2025-'[7]★Cost datasheet_v2'!$D16) -> 6091.8 | G16: ='[7]★Cost datasheet_v2'!E16*(1+'[7]★Cost datasheet_v2'!O16)^(2030-'[7]★Cost datasheet_v2'!$D16) -> 6171738.9 | H16: ='[7]★Cost datasheet_v2'!F16*(1+'[7]★Cost datasheet_v2'!P16)^(2030-'[7]★Cost datasheet_v2'!$D16) -> 169352.04 | I16: ='[7]★Cost datasheet_v2'!G16*(1+'[7]★Cost datasheet_v2'!Q16)^(2030-'[7]★Cost datasheet_v2'!$D16) -> #REF! | J16: ='[7]★Cost datasheet_v2'!H16*(1+'[7]★Cost datasheet_v2'!R16)^(2030-'[7]★Cost datasheet_v2'!$D16) -> 6091.8 | K16: ='[7]★Cost datasheet_v2'!E16*(1+'[7]★Cost datasheet_v2'!O16)^(2038-'[7]★Cost datasheet_v2'!$D16) -> 7549059.8 | L16: ='[7]★Cost datasheet_v2'!F16*(1+'[7]★Cost datasheet_v2'!P16)^(2038-'[7]★Cost datasheet_v2'!$D16) -> 169352.04 | M16: ='[7]★Cost datasheet_v2'!G16*(1+'[7]★Cost datasheet_v2'!Q16)^(2038-'[7]★Cost datasheet_v2'!$D16) -> #REF! | N16: ='[7]★Cost datasheet_v2'!H16*(1+'[7]★Cost datasheet_v2'!R16)^(2038-'[7]★Cost datasheet_v2'!$D16) -> 6091.8 | O16: ='[7]★Cost datasheet_v2'!E16*(1+'[7]★Cost datasheet_v2'!O16)^(2040-'[7]★Cost datasheet_v2'!$D16) -> 7938970.6 | P16: ='[7]★Cost datasheet_v2'!F16*(1+'[7]★Cost datasheet_v2'!P16)^(2040-'[7]★Cost datasheet_v2'!$D16) -> 169352.04 | Q16: ='[7]★Cost datasheet_v2'!G16*(1+'[7]★Cost datasheet_v2'!Q16)^(2040-'[7]★Cost datasheet_v2'!$D16) -> #REF! | R16: ='[7]★Cost datasheet_v2'!H16*(1+'[7]★Cost datasheet_v2'!R16)^(2040-'[7]★Cost datasheet_v2'!$D16) -> 6091.8 | S16: ='[7]★Cost datasheet_v2'!E16*(1+'[7]★Cost datasheet_v2'!O16)^(2050-'[7]★Cost datasheet_v2'!$D16) -> 10212236 | T16: ='[7]★Cost datasheet_v2'!F16*(1+'[7]★Cost datasheet_v2'!P16)^(2050-'[7]★Cost datasheet_v2'!$D16) -> 169352.04 | U16: ='[7]★Cost datasheet_v2'!G16*(1+'[7]★Cost datasheet_v2'!Q16)^(2050-'[7]★Cost datasheet_v2'!$D16) -> #REF! | V16: ='[7]★Cost datasheet_v2'!H16*(1+'[7]★Cost datasheet_v2'!R16)^(2050-'[7]★Cost datasheet_v2'!$D16) -> 6091.8
B17: CHP | C17: ='[7]★Cost datasheet_v2'!E17*(1+'[7]★Cost datasheet_v2'!O17/100)^(2025-'[7]★Cost datasheet_v2'!$D17) -> #REF! | D17: ='[7]★Cost datasheet_v2'!F17*(1+'[7]★Cost datasheet_v2'!P17/100)^(2025-'[7]★Cost datasheet_v2'!$D17) -> #REF! | E17: ='[7]★Cost datasheet_v2'!G17*(1+'[7]★Cost datasheet_v2'!Q17/100)^(2025-'[7]★Cost datasheet_v2'!$D17) -> #REF! | F17: ='[7]★Cost datasheet_v2'!H17*(1+'[7]★Cost datasheet_v2'!R17/100)^(2025-'[7]★Cost datasheet_v2'!$D17) -> #REF! | G17: ='[7]★Cost datasheet_v2'!E17*(1+'[7]★Cost datasheet_v2'!O17)^(2030-'[7]★Cost datasheet_v2'!$D17) -> #REF! | H17: ='[7]★Cost datasheet_v2'!F17*(1+'[7]★Cost datasheet_v2'!P17)^(2030-'[7]★Cost datasheet_v2'!$D17) -> #REF! | I17: ='[7]★Cost datasheet_v2'!G17*(1+'[7]★Cost datasheet_v2'!Q17)^(2030-'[7]★Cost datasheet_v2'!$D17) -> #REF! | J17: ='[7]★Cost datasheet_v2'!H17*(1+'[7]★Cost datasheet_v2'!R17)^(2030-'[7]★Cost datasheet_v2'!$D17) -> #REF! | K17: ='[7]★Cost datasheet_v2'!E17*(1+'[7]★Cost datasheet_v2'!O17)^(2038-'[7]★Cost datasheet_v2'!$D17) -> #REF! | L17: ='[7]★Cost datasheet_v2'!F17*(1+'[7]★Cost datasheet_v2'!P17)^(2038-'[7]★Cost datasheet_v2'!$D17) -> #REF! | M17: ='[7]★Cost datasheet_v2'!G17*(1+'[7]★Cost datasheet_v2'!Q17)^(2038-'[7]★Cost datasheet_v2'!$D17) -> #REF! | N17: ='[7]★Cost datasheet_v2'!H17*(1+'[7]★Cost datasheet_v2'!R17)^(2038-'[7]★Cost datasheet_v2'!$D17) -> #REF! | O17: ='[7]★Cost datasheet_v2'!E17*(1+'[7]★Cost datasheet_v2'!O17)^(2040-'[7]★Cost datasheet_v2'!$D17) -> #REF! | P17: ='[7]★Cost datasheet_v2'!F17*(1+'[7]★Cost datasheet_v2'!P17)^(2040-'[7]★Cost datasheet_v2'!$D17) -> #REF! | Q17: ='[7]★Cost datasheet_v2'!G17*(1+'[7]★Cost datasheet_v2'!Q17)^(2040-'[7]★Cost datasheet_v2'!$D17) -> #REF! | R17: ='[7]★Cost datasheet_v2'!H17*(1+'[7]★Cost datasheet_v2'!R17)^(2040-'[7]★Cost datasheet_v2'!$D17) -> #REF! | S17: ='[7]★Cost datasheet_v2'!E17*(1+'[7]★Cost datasheet_v2'!O17)^(2050-'[7]★Cost datasheet_v2'!$D17) -> #REF! | T17: ='[7]★Cost datasheet_v2'!F17*(1+'[7]★Cost datasheet_v2'!P17)^(2050-'[7]★Cost datasheet_v2'!$D17) -> #REF! | U17: ='[7]★Cost datasheet_v2'!G17*(1+'[7]★Cost datasheet_v2'!Q17)^(2050-'[7]★Cost datasheet_v2'!$D17) -> #REF! | V17: ='[7]★Cost datasheet_v2'!H17*(1+'[7]★Cost datasheet_v2'!R17)^(2050-'[7]★Cost datasheet_v2'!$D17) -> #REF!
A19: Flexibility | B19: ESS(4Hr) | C19: ='[7]★Cost datasheet_v2'!E19*(1+'[7]★Cost datasheet_v2'!O19)^(2025-'[7]★Cost datasheet_v2'!$D19) -> 2406605 | D19: ='[7]★Cost datasheet_v2'!F19*(1+'[7]★Cost datasheet_v2'!P19)^(2025-'[7]★Cost datasheet_v2'!$D19) -> 55313.972 | E19: ='[7]★Cost datasheet_v2'!G19*(1+'[7]★Cost datasheet_v2'!Q19)^(2025-'[7]★Cost datasheet_v2'!$D19) -> #REF! | F19: ='[7]★Cost datasheet_v2'!H19*(1+'[7]★Cost datasheet_v2'!R19)^(2025-'[7]★Cost datasheet_v2'!$D19) -> #REF! | G19: ='[7]★Cost datasheet_v2'!E19*(1+'[7]★Cost datasheet_v2'!O19)^(2030-'[7]★Cost datasheet_v2'!$D19) -> 2115044.1 | H19: ='[7]★Cost datasheet_v2'!F19*(1+'[7]★Cost datasheet_v2'!P19)^(2030-'[7]★Cost datasheet_v2'!$D19) -> 48126.002 | I19: ='[7]★Cost datasheet_v2'!G19*(1+'[7]★Cost datasheet_v2'!Q19)^(2030-'[7]★Cost datasheet_v2'!$D19) -> #REF! | J19: ='[7]★Cost datasheet_v2'!H19*(1+'[7]★Cost datasheet_v2'!R19)^(2030-'[7]★Cost datasheet_v2'!$D19) -> #REF! | K19: ='[7]★Cost datasheet_v2'!E19*(1+'[7]★Cost datasheet_v2'!O19)^(2038-'[7]★Cost datasheet_v2'!$D19) -> 1720215.2 | L19: ='[7]★Cost datasheet_v2'!F19*(1+'[7]★Cost datasheet_v2'!P19)^(2038-'[7]★Cost datasheet_v2'!$D19) -> 38516.933 | M19: ='[7]★Cost datasheet_v2'!G19*(1+'[7]★Cost datasheet_v2'!Q19)^(2038-'[7]★Cost datasheet_v2'!$D19) -> #REF! | N19: ='[7]★Cost datasheet_v2'!H19*(1+'[7]★Cost datasheet_v2'!R19)^(2038-'[7]★Cost datasheet_v2'!$D19) -> #REF! | O19: ='[7]★Cost datasheet_v2'!E19*(1+'[7]★Cost datasheet_v2'!O19)^(2040-'[7]★Cost datasheet_v2'!$D19) -> 1633610.9 | P19: ='[7]★Cost datasheet_v2'!F19*(1+'[7]★Cost datasheet_v2'!P19)^(2040-'[7]★Cost datasheet_v2'!$D19) -> 36430.881 | Q19: ='[7]★Cost datasheet_v2'!G19*(1+'[7]★Cost datasheet_v2'!Q19)^(2040-'[7]★Cost datasheet_v2'!$D19) -> #REF! | R19: ='[7]★Cost datasheet_v2'!H19*(1+'[7]★Cost datasheet_v2'!R19)^(2040-'[7]★Cost datasheet_v2'!$D19) -> #REF! | S19: ='[7]★Cost datasheet_v2'!E19*(1+'[7]★Cost datasheet_v2'!O19)^(2050-'[7]★Cost datasheet_v2'!$D19) -> 1261763.2 | T19: ='[7]★Cost datasheet_v2'!F19*(1+'[7]★Cost datasheet_v2'!P19)^(2050-'[7]★Cost datasheet_v2'!$D19) -> 27577.796 | U19: ='[7]★Cost datasheet_v2'!G19*(1+'[7]★Cost datasheet_v2'!Q19)^(2050-'[7]★Cost datasheet_v2'!$D19) -> #REF! | V19: ='[7]★Cost datasheet_v2'!H19*(1+'[7]★Cost datasheet_v2'!R19)^(2050-'[7]★Cost datasheet_v2'!$D19) -> #REF!
B20: EV | C20: ='[7]★Cost datasheet_v2'!E20*(1+'[7]★Cost datasheet_v2'!O20)^(2025-'[7]★Cost datasheet_v2'!$D20) -> #REF! | D20: ='[7]★Cost datasheet_v2'!F20*(1+'[7]★Cost datasheet_v2'!P20)^(2025-'[7]★Cost datasheet_v2'!$D20) -> #REF! | E20: ='[7]★Cost datasheet_v2'!G20*(1+'[7]★Cost datasheet_v2'!Q20)^(2025-'[7]★Cost datasheet_v2'!$D20) -> #REF! | F20: ='[7]★Cost datasheet_v2'!H20*(1+'[7]★Cost datasheet_v2'!R20)^(2025-'[7]★Cost datasheet_v2'!$D20) -> #REF! | G20: ='[7]★Cost datasheet_v2'!E20*(1+'[7]★Cost datasheet_v2'!O20)^(2030-'[7]★Cost datasheet_v2'!$D20) -> #REF! | H20: ='[7]★Cost datasheet_v2'!F20*(1+'[7]★Cost datasheet_v2'!P20)^(2030-'[7]★Cost datasheet_v2'!$D20) -> #REF! | I20: ='[7]★Cost datasheet_v2'!G20*(1+'[7]★Cost datasheet_v2'!Q20)^(2030-'[7]★Cost datasheet_v2'!$D20) -> #REF! | J20: ='[7]★Cost datasheet_v2'!H20*(1+'[7]★Cost datasheet_v2'!R20)^(2030-'[7]★Cost datasheet_v2'!$D20) -> #REF! | K20: ='[7]★Cost datasheet_v2'!E20*(1+'[7]★Cost datasheet_v2'!O20)^(2038-'[7]★Cost datasheet_v2'!$D20) -> #REF! | L20: ='[7]★Cost datasheet_v2'!F20*(1+'[7]★Cost datasheet_v2'!P20)^(2038-'[7]★Cost datasheet_v2'!$D20) -> #REF! | M20: ='[7]★Cost datasheet_v2'!G20*(1+'[7]★Cost datasheet_v2'!Q20)^(2038-'[7]★Cost datasheet_v2'!$D20) -> #REF! | N20: ='[7]★Cost datasheet_v2'!H20*(1+'[7]★Cost datasheet_v2'!R20)^(2038-'[7]★Cost datasheet_v2'!$D20) -> #REF! | O20: ='[7]★Cost datasheet_v2'!E20*(1+'[7]★Cost datasheet_v2'!O20)^(2040-'[7]★Cost datasheet_v2'!$D20) -> #REF! | P20: ='[7]★Cost datasheet_v2'!F20*(1+'[7]★Cost datasheet_v2'!P20)^(2040-'[7]★Cost datasheet_v2'!$D20) -> #REF! | Q20: ='[7]★Cost datasheet_v2'!G20*(1+'[7]★Cost datasheet_v2'!Q20)^(2040-'[7]★Cost datasheet_v2'!$D20) -> #REF! | R20: ='[7]★Cost datasheet_v2'!H20*(1+'[7]★Cost datasheet_v2'!R20)^(2040-'[7]★Cost datasheet_v2'!$D20) -> #REF! | S20: ='[7]★Cost datasheet_v2'!E20*(1+'[7]★Cost datasheet_v2'!O20)^(2050-'[7]★Cost datasheet_v2'!$D20) -> #REF! | T20: ='[7]★Cost datasheet_v2'!F20*(1+'[7]★Cost datasheet_v2'!P20)^(2050-'[7]★Cost datasheet_v2'!$D20) -> #REF! | U20: ='[7]★Cost datasheet_v2'!G20*(1+'[7]★Cost datasheet_v2'!Q20)^(2050-'[7]★Cost datasheet_v2'!$D20) -> #REF! | V20: ='[7]★Cost datasheet_v2'!H20*(1+'[7]★Cost datasheet_v2'!R20)^(2050-'[7]★Cost datasheet_v2'!$D20) -> #REF!
B21: Electrolyzer (PEM) 100MW | C21: ='[7]★Cost datasheet_v2'!E21*(1+'[7]★Cost datasheet_v2'!O21)^(2025-'[7]★Cost datasheet_v2'!$D21) -> 1558727.4 | D21: ='[7]★Cost datasheet_v2'!F21*(1+'[7]★Cost datasheet_v2'!P21)^(2025-'[7]★Cost datasheet_v2'!$D21) -> 34985.08 | E21: ='[7]★Cost datasheet_v2'!G21*(1+'[7]★Cost datasheet_v2'!Q21)^(2025-'[7]★Cost datasheet_v2'!$D21) -> #REF! | F21: ='[7]★Cost datasheet_v2'!H21*(1+'[7]★Cost datasheet_v2'!R21)^(2025-'[7]★Cost datasheet_v2'!$D21) -> #REF! | G21: ='[7]★Cost datasheet_v2'!E21*(1+'[7]★Cost datasheet_v2'!O21)^(2030-'[7]★Cost datasheet_v2'!$D21) -> 1388952.7 | H21: ='[7]★Cost datasheet_v2'!F21*(1+'[7]★Cost datasheet_v2'!P21)^(2030-'[7]★Cost datasheet_v2'!$D21) -> 34985.08 | I21: ='[7]★Cost datasheet_v2'!G21*(1+'[7]★Cost datasheet_v2'!Q21)^(2030-'[7]★Cost datasheet_v2'!$D21) -> #REF! | J21: ='[7]★Cost datasheet_v2'!H21*(1+'[7]★Cost datasheet_v2'!R21)^(2030-'[7]★Cost datasheet_v2'!$D21) -> #REF! | K21: ='[7]★Cost datasheet_v2'!E21*(1+'[7]★Cost datasheet_v2'!O21)^(2038-'[7]★Cost datasheet_v2'!$D21) -> 1154928.6 | L21: ='[7]★Cost datasheet_v2'!F21*(1+'[7]★Cost datasheet_v2'!P21)^(2038-'[7]★Cost datasheet_v2'!$D21) -> 34985.08 | M21: ='[7]★Cost datasheet_v2'!G21*(1+'[7]★Cost datasheet_v2'!Q21)^(2038-'[7]★Cost datasheet_v2'!$D21) -> #REF! | N21: ='[7]★Cost datasheet_v2'!H21*(1+'[7]★Cost datasheet_v2'!R21)^(2038-'[7]★Cost datasheet_v2'!$D21) -> #REF! | O21: ='[7]★Cost datasheet_v2'!E21*(1+'[7]★Cost datasheet_v2'!O21)^(2040-'[7]★Cost datasheet_v2'!$D21) -> 1102864.2 | P21: ='[7]★Cost datasheet_v2'!F21*(1+'[7]★Cost datasheet_v2'!P21)^(2040-'[7]★Cost datasheet_v2'!$D21) -> 34985.08 | Q21: ='[7]★Cost datasheet_v2'!G21*(1+'[7]★Cost datasheet_v2'!Q21)^(2040-'[7]★Cost datasheet_v2'!$D21) -> #REF! | R21: ='[7]★Cost datasheet_v2'!H21*(1+'[7]★Cost datasheet_v2'!R21)^(2040-'[7]★Cost datasheet_v2'!$D21) -> #REF! | S21: ='[7]★Cost datasheet_v2'!E21*(1+'[7]★Cost datasheet_v2'!O21)^(2050-'[7]★Cost datasheet_v2'!$D21) -> 875702.57 | T21: ='[7]★Cost datasheet_v2'!F21*(1+'[7]★Cost datasheet_v2'!P21)^(2050-'[7]★Cost datasheet_v2'!$D21) -> 34985.08 | U21: ='[7]★Cost datasheet_v2'!G21*(1+'[7]★Cost datasheet_v2'!Q21)^(2050-'[7]★Cost datasheet_v2'!$D21) -> #REF! | V21: ='[7]★Cost datasheet_v2'!H21*(1+'[7]★Cost datasheet_v2'!R21)^(2050-'[7]★Cost datasheet_v2'!$D21) -> #REF!
B22: Electrolyzer (AEC) 100MW | C22: ='[7]★Cost datasheet_v2'!E22*(1+'[7]★Cost datasheet_v2'!O22)^(2025-'[7]★Cost datasheet_v2'!$D22) -> 1438825.3 | D22: ='[7]★Cost datasheet_v2'!F22*(1+'[7]★Cost datasheet_v2'!P22)^(2025-'[7]★Cost datasheet_v2'!$D22) -> 64587.84 | E22: ='[7]★Cost datasheet_v2'!G22*(1+'[7]★Cost datasheet_v2'!Q22)^(2025-'[7]★Cost datasheet_v2'!$D22) -> #REF! | F22: ='[7]★Cost datasheet_v2'!H22*(1+'[7]★Cost datasheet_v2'!R22)^(2025-'[7]★Cost datasheet_v2'!$D22) -> #REF! | G22: ='[7]★Cost datasheet_v2'!E22*(1+'[7]★Cost datasheet_v2'!O22)^(2030-'[7]★Cost datasheet_v2'!$D22) -> 1282110.2 | H22: ='[7]★Cost datasheet_v2'!F22*(1+'[7]★Cost datasheet_v2'!P22)^(2030-'[7]★Cost datasheet_v2'!$D22) -> 64587.84 | I22: ='[7]★Cost datasheet_v2'!G22*(1+'[7]★Cost datasheet_v2'!Q22)^(2030-'[7]★Cost datasheet_v2'!$D22) -> #REF! | J22: ='[7]★Cost datasheet_v2'!H22*(1+'[7]★Cost datasheet_v2'!R22)^(2030-'[7]★Cost datasheet_v2'!$D22) -> #REF! | K22: ='[7]★Cost datasheet_v2'!E22*(1+'[7]★Cost datasheet_v2'!O22)^(2038-'[7]★Cost datasheet_v2'!$D22) -> 1066087.9 | L22: ='[7]★Cost datasheet_v2'!F22*(1+'[7]★Cost datasheet_v2'!P22)^(2038-'[7]★Cost datasheet_v2'!$D22) -> 64587.84 | M22: ='[7]★Cost datasheet_v2'!G22*(1+'[7]★Cost datasheet_v2'!Q22)^(2038-'[7]★Cost datasheet_v2'!$D22) -> #REF! | N22: ='[7]★Cost datasheet_v2'!H22*(1+'[7]★Cost datasheet_v2'!R22)^(2038-'[7]★Cost datasheet_v2'!$D22) -> #REF! | O22: ='[7]★Cost datasheet_v2'!E22*(1+'[7]★Cost datasheet_v2'!O22)^(2040-'[7]★Cost datasheet_v2'!$D22) -> 1018028.5 | P22: ='[7]★Cost datasheet_v2'!F22*(1+'[7]★Cost datasheet_v2'!P22)^(2040-'[7]★Cost datasheet_v2'!$D22) -> 64587.84 | Q22: ='[7]★Cost datasheet_v2'!G22*(1+'[7]★Cost datasheet_v2'!Q22)^(2040-'[7]★Cost datasheet_v2'!$D22) -> #REF! | R22: ='[7]★Cost datasheet_v2'!H22*(1+'[7]★Cost datasheet_v2'!R22)^(2040-'[7]★Cost datasheet_v2'!$D22) -> #REF! | S22: ='[7]★Cost datasheet_v2'!E22*(1+'[7]★Cost datasheet_v2'!O22)^(2050-'[7]★Cost datasheet_v2'!$D22) -> 808340.83 | T22: ='[7]★Cost datasheet_v2'!F22*(1+'[7]★Cost datasheet_v2'!P22)^(2050-'[7]★Cost datasheet_v2'!$D22) -> 64587.84 | U22: ='[7]★Cost datasheet_v2'!G22*(1+'[7]★Cost datasheet_v2'!Q22)^(2050-'[7]★Cost datasheet_v2'!$D22) -> #REF! | V22: ='[7]★Cost datasheet_v2'!H22*(1+'[7]★Cost datasheet_v2'!R22)^(2050-'[7]★Cost datasheet_v2'!$D22) -> #REF!
B23: Fuel Cell (SOFC-CHP) 2.5MW_e | C23: ='[7]★Cost datasheet_v2'!E23*(1+'[7]★Cost datasheet_v2'!O23)^(2025-'[7]★Cost datasheet_v2'!$D23) -> 4353752.9 | D23: ='[7]★Cost datasheet_v2'!F23*(1+'[7]★Cost datasheet_v2'!P23)^(2025-'[7]★Cost datasheet_v2'!$D23) -> 236090.76 | E23: ='[7]★Cost datasheet_v2'!G23*(1+'[7]★Cost datasheet_v2'!Q23)^(2025-'[7]★Cost datasheet_v2'!$D23) -> #REF! | F23: ='[7]★Cost datasheet_v2'!H23*(1+'[7]★Cost datasheet_v2'!R23)^(2025-'[7]★Cost datasheet_v2'!$D23) -> #REF! | G23: ='[7]★Cost datasheet_v2'!E23*(1+'[7]★Cost datasheet_v2'!O23)^(2030-'[7]★Cost datasheet_v2'!$D23) -> 4014380.9 | H23: ='[7]★Cost datasheet_v2'!F23*(1+'[7]★Cost datasheet_v2'!P23)^(2030-'[7]★Cost datasheet_v2'!$D23) -> 236090.76 | I23: ='[7]★Cost datasheet_v2'!G23*(1+'[7]★Cost datasheet_v2'!Q23)^(2030-'[7]★Cost datasheet_v2'!$D23) -> #REF! | J23: ='[7]★Cost datasheet_v2'!H23*(1+'[7]★Cost datasheet_v2'!R23)^(2030-'[7]★Cost datasheet_v2'!$D23) -> #REF! | K23: ='[7]★Cost datasheet_v2'!E23*(1+'[7]★Cost datasheet_v2'!O23)^(2038-'[7]★Cost datasheet_v2'!$D23) -> 3525545 | L23: ='[7]★Cost datasheet_v2'!F23*(1+'[7]★Cost datasheet_v2'!P23)^(2038-'[7]★Cost datasheet_v2'!$D23) -> 236090.76 | M23: ='[7]★Cost datasheet_v2'!G23*(1+'[7]★Cost datasheet_v2'!Q23)^(2038-'[7]★Cost datasheet_v2'!$D23) -> #REF! | N23: ='[7]★Cost datasheet_v2'!H23*(1+'[7]★Cost datasheet_v2'!R23)^(2038-'[7]★Cost datasheet_v2'!$D23) -> #REF! | O23: ='[7]★Cost datasheet_v2'!E23*(1+'[7]★Cost datasheet_v2'!O23)^(2040-'[7]★Cost datasheet_v2'!$D23) -> 3412936.3 | P23: ='[7]★Cost datasheet_v2'!F23*(1+'[7]★Cost datasheet_v2'!P23)^(2040-'[7]★Cost datasheet_v2'!$D23) -> 236090.76 | Q23: ='[7]★Cost datasheet_v2'!G23*(1+'[7]★Cost datasheet_v2'!Q23)^(2040-'[7]★Cost datasheet_v2'!$D23) -> #REF! | R23: ='[7]★Cost datasheet_v2'!H23*(1+'[7]★Cost datasheet_v2'!R23)^(2040-'[7]★Cost datasheet_v2'!$D23) -> #REF! | S23: ='[7]★Cost datasheet_v2'!E23*(1+'[7]★Cost datasheet_v2'!O23)^(2050-'[7]★Cost datasheet_v2'!$D23) -> 2901601.7 | T23: ='[7]★Cost datasheet_v2'!F23*(1+'[7]★Cost datasheet_v2'!P23)^(2050-'[7]★Cost datasheet_v2'!$D23) -> 236090.76 | U23: ='[7]★Cost datasheet_v2'!G23*(1+'[7]★Cost datasheet_v2'!Q23)^(2050-'[7]★Cost datasheet_v2'!$D23) -> #REF! | V23: ='[7]★Cost datasheet_v2'!H23*(1+'[7]★Cost datasheet_v2'!R23)^(2050-'[7]★Cost datasheet_v2'!$D23) -> #REF!
B24: Fuel Cell (LT-PEMFC CHP) 0.1MW_e | C24: ='[7]★Cost datasheet_v2'!E24*(1+'[7]★Cost datasheet_v2'!O24)^(2025-'[7]★Cost datasheet_v2'!$D24) -> 1715114.8 | D24: ='[7]★Cost datasheet_v2'!F24*(1+'[7]★Cost datasheet_v2'!P24)^(2025-'[7]★Cost datasheet_v2'!$D24) -> 93005.449 | E24: ='[7]★Cost datasheet_v2'!G24*(1+'[7]★Cost datasheet_v2'!Q24)^(2025-'[7]★Cost datasheet_v2'!$D24) -> #REF! | F24: ='[7]★Cost datasheet_v2'!H24*(1+'[7]★Cost datasheet_v2'!R24)^(2025-'[7]★Cost datasheet_v2'!$D24) -> #REF! | G24: ='[7]★Cost datasheet_v2'!E24*(1+'[7]★Cost datasheet_v2'!O24)^(2030-'[7]★Cost datasheet_v2'!$D24) -> 1581422.8 | H24: ='[7]★Cost datasheet_v2'!F24*(1+'[7]★Cost datasheet_v2'!P24)^(2030-'[7]★Cost datasheet_v2'!$D24) -> 93005.449 | I24: ='[7]★Cost datasheet_v2'!G24*(1+'[7]★Cost datasheet_v2'!Q24)^(2030-'[7]★Cost datasheet_v2'!$D24) -> #REF! | J24: ='[7]★Cost datasheet_v2'!H24*(1+'[7]★Cost datasheet_v2'!R24)^(2030-'[7]★Cost datasheet_v2'!$D24) -> #REF! | K24: ='[7]★Cost datasheet_v2'!E24*(1+'[7]★Cost datasheet_v2'!O24)^(2038-'[7]★Cost datasheet_v2'!$D24) -> 1388851.1 | L24: ='[7]★Cost datasheet_v2'!F24*(1+'[7]★Cost datasheet_v2'!P24)^(2038-'[7]★Cost datasheet_v2'!$D24) -> 93005.449 | M24: ='[7]★Cost datasheet_v2'!G24*(1+'[7]★Cost datasheet_v2'!Q24)^(2038-'[7]★Cost datasheet_v2'!$D24) -> #REF! | N24: ='[7]★Cost datasheet_v2'!H24*(1+'[7]★Cost datasheet_v2'!R24)^(2038-'[7]★Cost datasheet_v2'!$D24) -> #REF! | O24: ='[7]★Cost datasheet_v2'!E24*(1+'[7]★Cost datasheet_v2'!O24)^(2040-'[7]★Cost datasheet_v2'!$D24) -> 1344490.1 | P24: ='[7]★Cost datasheet_v2'!F24*(1+'[7]★Cost datasheet_v2'!P24)^(2040-'[7]★Cost datasheet_v2'!$D24) -> 93005.449 | Q24: ='[7]★Cost datasheet_v2'!G24*(1+'[7]★Cost datasheet_v2'!Q24)^(2040-'[7]★Cost datasheet_v2'!$D24) -> #REF! | R24: ='[7]★Cost datasheet_v2'!H24*(1+'[7]★Cost datasheet_v2'!R24)^(2040-'[7]★Cost datasheet_v2'!$D24) -> #REF! | S24: ='[7]★Cost datasheet_v2'!E24*(1+'[7]★Cost datasheet_v2'!O24)^(2050-'[7]★Cost datasheet_v2'!$D24) -> 1143055.2 | T24: ='[7]★Cost datasheet_v2'!F24*(1+'[7]★Cost datasheet_v2'!P24)^(2050-'[7]★Cost datasheet_v2'!$D24) -> 93005.449 | U24: ='[7]★Cost datasheet_v2'!G24*(1+'[7]★Cost datasheet_v2'!Q24)^(2050-'[7]★Cost datasheet_v2'!$D24) -> #REF! | V24: ='[7]★Cost datasheet_v2'!H24*(1+'[7]★Cost datasheet_v2'!R24)^(2050-'[7]★Cost datasheet_v2'!$D24) -> #REF!
B25: Heatpump (kW) | C25: ='[7]★Cost datasheet_v2'!E25*(1+'[7]★Cost datasheet_v2'!O25)^(2025-'[7]★Cost datasheet_v2'!$D25) -> 1400000 | D25: ='[7]★Cost datasheet_v2'!F25*(1+'[7]★Cost datasheet_v2'!P25)^(2025-'[7]★Cost datasheet_v2'!$D25) -> 60015.604 | E25: ='[7]★Cost datasheet_v2'!G25*(1+'[7]★Cost datasheet_v2'!Q25)^(2025-'[7]★Cost datasheet_v2'!$D25) -> #REF! | F25: ='[7]★Cost datasheet_v2'!H25*(1+'[7]★Cost datasheet_v2'!R25)^(2025-'[7]★Cost datasheet_v2'!$D25) -> #REF! | G25: ='[7]★Cost datasheet_v2'!E25*(1+'[7]★Cost datasheet_v2'!O25)^(2030-'[7]★Cost datasheet_v2'!$D25) -> 1345150.1 | H25: ='[7]★Cost datasheet_v2'!F25*(1+'[7]★Cost datasheet_v2'!P25)^(2030-'[7]★Cost datasheet_v2'!$D25) -> 55737.682 | I25: ='[7]★Cost datasheet_v2'!G25*(1+'[7]★Cost datasheet_v2'!Q25)^(2030-'[7]★Cost datasheet_v2'!$D25) -> #REF! | J25: ='[7]★Cost datasheet_v2'!H25*(1+'[7]★Cost datasheet_v2'!R25)^(2030-'[7]★Cost datasheet_v2'!$D25) -> #REF! | K25: ='[7]★Cost datasheet_v2'!E25*(1+'[7]★Cost datasheet_v2'!O25)^(2038-'[7]★Cost datasheet_v2'!$D25) -> 1261824.9 | L25: ='[7]★Cost datasheet_v2'!F25*(1+'[7]★Cost datasheet_v2'!P25)^(2038-'[7]★Cost datasheet_v2'!$D25) -> 49518.154 | M25: ='[7]★Cost datasheet_v2'!G25*(1+'[7]★Cost datasheet_v2'!Q25)^(2038-'[7]★Cost datasheet_v2'!$D25) -> #REF! | N25: ='[7]★Cost datasheet_v2'!H25*(1+'[7]★Cost datasheet_v2'!R25)^(2038-'[7]★Cost datasheet_v2'!$D25) -> #REF! | O25: ='[7]★Cost datasheet_v2'!E25*(1+'[7]★Cost datasheet_v2'!O25)^(2040-'[7]★Cost datasheet_v2'!$D25) -> 1241812.9 | P25: ='[7]★Cost datasheet_v2'!F25*(1+'[7]★Cost datasheet_v2'!P25)^(2040-'[7]★Cost datasheet_v2'!$D25) -> 48074.894 | Q25: ='[7]★Cost datasheet_v2'!G25*(1+'[7]★Cost datasheet_v2'!Q25)^(2040-'[7]★Cost datasheet_v2'!$D25) -> #REF! | R25: ='[7]★Cost datasheet_v2'!H25*(1+'[7]★Cost datasheet_v2'!R25)^(2040-'[7]★Cost datasheet_v2'!$D25) -> #REF! | S25: ='[7]★Cost datasheet_v2'!E25*(1+'[7]★Cost datasheet_v2'!O25)^(2050-'[7]★Cost datasheet_v2'!$D25) -> 1146414.2 | T25: ='[7]★Cost datasheet_v2'!F25*(1+'[7]★Cost datasheet_v2'!P25)^(2050-'[7]★Cost datasheet_v2'!$D25) -> 41465.583 | U25: ='[7]★Cost datasheet_v2'!G25*(1+'[7]★Cost datasheet_v2'!Q25)^(2050-'[7]★Cost datasheet_v2'!$D25) -> #REF! | V25: ='[7]★Cost datasheet_v2'!H25*(1+'[7]★Cost datasheet_v2'!R25)^(2050-'[7]★Cost datasheet_v2'!$D25) -> #REF!
C26: CAPEX/ MCI (원/KWh Capacity) | D26: Fixed O&M (원/kW/yr) | E26: - | F26: - | G26: CAPEX/ MCI (원/KWh Capacity) | H26: Fixed O&M (원/kW/yr) | I26: - | J26: - | K26: CAPEX/ MCI (원/KWh Capacity) | L26: Fixed O&M (원/kW/yr) | M26: - | N26: - | O26: CAPEX/ MCI (원/KWh Capacity) | P26: Fixed O&M (원/kW/yr) | Q26: - | R26: - | S26: CAPEX/ MCI (원/KWh Capacity) | T26: Fixed O&M (원/kW/yr) | U26: - | V26: -
A27: Storage | B27: Hydrogen Storage (Physical) | C27: ='[7]★Cost datasheet_v2'!E27*(1+'[7]★Cost datasheet_v2'!O27)^(2025-'[7]★Cost datasheet_v2'!$D27) -> 82080.38 | D27: ='[7]★Cost datasheet_v2'!F27*(1+'[7]★Cost datasheet_v2'!P27)^(2025-'[7]★Cost datasheet_v2'!$D27) -> 858.53386 | E27: ='[7]★Cost datasheet_v2'!G27*(1+'[7]★Cost datasheet_v2'!Q27)^(2025-'[7]★Cost datasheet_v2'!$D27) -> #REF! | F27: ='[7]★Cost datasheet_v2'!H27*(1+'[7]★Cost datasheet_v2'!R27)^(2025-'[7]★Cost datasheet_v2'!$D27) -> #REF! | G27: ='[7]★Cost datasheet_v2'!E27*(1+'[7]★Cost datasheet_v2'!O27)^(2030-'[7]★Cost datasheet_v2'!$D27) -> 82080.38 | H27: ='[7]★Cost datasheet_v2'!F27*(1+'[7]★Cost datasheet_v2'!P27)^(2030-'[7]★Cost datasheet_v2'!$D27) -> 858.53386 | I27: ='[7]★Cost datasheet_v2'!G27*(1+'[7]★Cost datasheet_v2'!Q27)^(2030-'[7]★Cost datasheet_v2'!$D27) -> #REF! | J27: ='[7]★Cost datasheet_v2'!H27*(1+'[7]★Cost datasheet_v2'!R27)^(2030-'[7]★Cost datasheet_v2'!$D27) -> #REF! | K27: ='[7]★Cost datasheet_v2'!E27*(1+'[7]★Cost datasheet_v2'!O27)^(2038-'[7]★Cost datasheet_v2'!$D27) -> 82080.38 | L27: ='[7]★Cost datasheet_v2'!F27*(1+'[7]★Cost datasheet_v2'!P27)^(2038-'[7]★Cost datasheet_v2'!$D27) -> 858.53386 | M27: ='[7]★Cost datasheet_v2'!G27*(1+'[7]★Cost datasheet_v2'!Q27)^(2038-'[7]★Cost datasheet_v2'!$D27) -> #REF! | N27: ='[7]★Cost datasheet_v2'!H27*(1+'[7]★Cost datasheet_v2'!R27)^(2038-'[7]★Cost datasheet_v2'!$D27) -> #REF! | O27: ='[7]★Cost datasheet_v2'!E27*(1+'[7]★Cost datasheet_v2'!O27)^(2040-'[7]★Cost datasheet_v2'!$D27) -> 82080.38 | P27: ='[7]★Cost datasheet_v2'!F27*(1+'[7]★Cost datasheet_v2'!P27)^(2040-'[7]★Cost datasheet_v2'!$D27) -> 858.53386 | Q27: ='[7]★Cost datasheet_v2'!G27*(1+'[7]★Cost datasheet_v2'!Q27)^(2040-'[7]★Cost datasheet_v2'!$D27) -> #REF! | R27: ='[7]★Cost datasheet_v2'!H27*(1+'[7]★Cost datasheet_v2'!R27)^(2040-'[7]★Cost datasheet_v2'!$D27) -> #REF! | S27: ='[7]★Cost datasheet_v2'!E27*(1+'[7]★Cost datasheet_v2'!O27)^(2050-'[7]★Cost datasheet_v2'!$D27) -> 82080.38 | T27: ='[7]★Cost datasheet_v2'!F27*(1+'[7]★Cost datasheet_v2'!P27)^(2050-'[7]★Cost datasheet_v2'!$D27) -> 858.53386 | U27: ='[7]★Cost datasheet_v2'!G27*(1+'[7]★Cost datasheet_v2'!Q27)^(2050-'[7]★Cost datasheet_v2'!$D27) -> #REF! | V27: ='[7]★Cost datasheet_v2'!H27*(1+'[7]★Cost datasheet_v2'!R27)^(2050-'[7]★Cost datasheet_v2'!$D27) -> #REF!
C28: CAPEX/ MCI (원/KWh Capacity) | D28: Fixed O&M (원/tank/yr) | E28: - | F28: - | G28: CAPEX/ MCI (원/KWh Capacity) | H28: Fixed O&M (원/tank/yr) | I28: - | J28: - | K28: CAPEX/ MCI (원/KWh Capacity) | L28: Fixed O&M (원/tank/yr) | M28: - | N28: - | O28: CAPEX/ MCI (원/KWh Capacity) | P28: Fixed O&M (원/tank/yr) | Q28: - | R28: - | S28: CAPEX/ MCI (원/KWh Capacity) | T28: Fixed O&M (원/tank/yr) | U28: - | V28: -
B29: Heat Storage (small-scale) | C29: ='[7]★Cost datasheet_v2'!E29*(1+'[7]★Cost datasheet_v2'!O29)^(2025-'[7]★Cost datasheet_v2'!$D29) -> 565143.6 | D29: ='[7]★Cost datasheet_v2'!F29*(1+'[7]★Cost datasheet_v2'!P29)^(2025-'[7]★Cost datasheet_v2'!$D29) -> 68624.58 | E29: ='[7]★Cost datasheet_v2'!G29*(1+'[7]★Cost datasheet_v2'!Q29)^(2025-'[7]★Cost datasheet_v2'!$D29) -> #REF! | F29: ='[7]★Cost datasheet_v2'!H29*(1+'[7]★Cost datasheet_v2'!R29)^(2025-'[7]★Cost datasheet_v2'!$D29) -> #REF! | G29: ='[7]★Cost datasheet_v2'!E29*(1+'[7]★Cost datasheet_v2'!O29)^(2030-'[7]★Cost datasheet_v2'!$D29) -> 565143.6 | H29: ='[7]★Cost datasheet_v2'!F29*(1+'[7]★Cost datasheet_v2'!P29)^(2030-'[7]★Cost datasheet_v2'!$D29) -> 68624.58 | I29: ='[7]★Cost datasheet_v2'!G29*(1+'[7]★Cost datasheet_v2'!Q29)^(2030-'[7]★Cost datasheet_v2'!$D29) -> #REF! | J29: ='[7]★Cost datasheet_v2'!H29*(1+'[7]★Cost datasheet_v2'!R29)^(2030-'[7]★Cost datasheet_v2'!$D29) -> #REF! | K29: ='[7]★Cost datasheet_v2'!E29*(1+'[7]★Cost datasheet_v2'!O29)^(2038-'[7]★Cost datasheet_v2'!$D29) -> 565143.6 | L29: ='[7]★Cost datasheet_v2'!F29*(1+'[7]★Cost datasheet_v2'!P29)^(2038-'[7]★Cost datasheet_v2'!$D29) -> 68624.58 | M29: ='[7]★Cost datasheet_v2'!G29*(1+'[7]★Cost datasheet_v2'!Q29)^(2038-'[7]★Cost datasheet_v2'!$D29) -> #REF! | N29: ='[7]★Cost datasheet_v2'!H29*(1+'[7]★Cost datasheet_v2'!R29)^(2038-'[7]★Cost datasheet_v2'!$D29) -> #REF! | O29: ='[7]★Cost datasheet_v2'!E29*(1+'[7]★Cost datasheet_v2'!O29)^(2040-'[7]★Cost datasheet_v2'!$D29) -> 565143.6 | P29: ='[7]★Cost datasheet_v2'!F29*(1+'[7]★Cost datasheet_v2'!P29)^(2040-'[7]★Cost datasheet_v2'!$D29) -> 68624.58 | Q29: ='[7]★Cost datasheet_v2'!G29*(1+'[7]★Cost datasheet_v2'!Q29)^(2040-'[7]★Cost datasheet_v2'!$D29) -> #REF! | R29: ='[7]★Cost datasheet_v2'!H29*(1+'[7]★Cost datasheet_v2'!R29)^(2040-'[7]★Cost datasheet_v2'!$D29) -> #REF! | S29: ='[7]★Cost datasheet_v2'!E29*(1+'[7]★Cost datasheet_v2'!O29)^(2050-'[7]★Cost datasheet_v2'!$D29) -> 565143.6 | T29: ='[7]★Cost datasheet_v2'!F29*(1+'[7]★Cost datasheet_v2'!P29)^(2050-'[7]★Cost datasheet_v2'!$D29) -> 68624.58 | U29: ='[7]★Cost datasheet_v2'!G29*(1+'[7]★Cost datasheet_v2'!Q29)^(2050-'[7]★Cost datasheet_v2'!$D29) -> #REF! | V29: ='[7]★Cost datasheet_v2'!H29*(1+'[7]★Cost datasheet_v2'!R29)^(2050-'[7]★Cost datasheet_v2'!$D29) -> #REF!
B30: 축열조 | C30: ='[7]★Cost datasheet_v2'!E30*(1+'[7]★Cost datasheet_v2'!O30)^(2025-'[7]★Cost datasheet_v2'!$D30) -> 57361.377 | D30: ='[7]★Cost datasheet_v2'!F30*(1+'[7]★Cost datasheet_v2'!P30)^(2025-'[7]★Cost datasheet_v2'!$D30) -> 6965.31 | E30: ='[7]★Cost datasheet_v2'!G30*(1+'[7]★Cost datasheet_v2'!Q30)^(2025-'[7]★Cost datasheet_v2'!$D30) -> #REF! | F30: ='[7]★Cost datasheet_v2'!H30*(1+'[7]★Cost datasheet_v2'!R30)^(2025-'[7]★Cost datasheet_v2'!$D30) -> #REF! | G30: ='[7]★Cost datasheet_v2'!E30*(1+'[7]★Cost datasheet_v2'!O30)^(2030-'[7]★Cost datasheet_v2'!$D30) -> 57361.377 | H30: ='[7]★Cost datasheet_v2'!F30*(1+'[7]★Cost datasheet_v2'!P30)^(2030-'[7]★Cost datasheet_v2'!$D30) -> 6965.31 | I30: ='[7]★Cost datasheet_v2'!G30*(1+'[7]★Cost datasheet_v2'!Q30)^(2030-'[7]★Cost datasheet_v2'!$D30) -> #REF! | J30: ='[7]★Cost datasheet_v2'!H30*(1+'[7]★Cost datasheet_v2'!R30)^(2030-'[7]★Cost datasheet_v2'!$D30) -> #REF! | K30: ='[7]★Cost datasheet_v2'!E30*(1+'[7]★Cost datasheet_v2'!O30)^(2038-'[7]★Cost datasheet_v2'!$D30) -> 57361.377 | L30: ='[7]★Cost datasheet_v2'!F30*(1+'[7]★Cost datasheet_v2'!P30)^(2038-'[7]★Cost datasheet_v2'!$D30) -> 6965.31 | M30: ='[7]★Cost datasheet_v2'!G30*(1+'[7]★Cost datasheet_v2'!Q30)^(2038-'[7]★Cost datasheet_v2'!$D30) -> #REF! | N30: ='[7]★Cost datasheet_v2'!H30*(1+'[7]★Cost datasheet_v2'!R30)^(2038-'[7]★Cost datasheet_v2'!$D30) -> #REF! | O30: ='[7]★Cost datasheet_v2'!E30*(1+'[7]★Cost datasheet_v2'!O30)^(2040-'[7]★Cost datasheet_v2'!$D30) -> 57361.377 | P30: ='[7]★Cost datasheet_v2'!F30*(1+'[7]★Cost datasheet_v2'!P30)^(2040-'[7]★Cost datasheet_v2'!$D30) -> 6965.31 | Q30: ='[7]★Cost datasheet_v2'!G30*(1+'[7]★Cost datasheet_v2'!Q30)^(2040-'[7]★Cost datasheet_v2'!$D30) -> #REF! | R30: ='[7]★Cost datasheet_v2'!H30*(1+'[7]★Cost datasheet_v2'!R30)^(2040-'[7]★Cost datasheet_v2'!$D30) -> #REF! | S30: ='[7]★Cost datasheet_v2'!E30*(1+'[7]★Cost datasheet_v2'!O30)^(2050-'[7]★Cost datasheet_v2'!$D30) -> 57361.377 | T30: ='[7]★Cost datasheet_v2'!F30*(1+'[7]★Cost datasheet_v2'!P30)^(2050-'[7]★Cost datasheet_v2'!$D30) -> 6965.31 | U30: ='[7]★Cost datasheet_v2'!G30*(1+'[7]★Cost datasheet_v2'!Q30)^(2050-'[7]★Cost datasheet_v2'!$D30) -> #REF! | V30: ='[7]★Cost datasheet_v2'!H30*(1+'[7]★Cost datasheet_v2'!R30)^(2050-'[7]★Cost datasheet_v2'!$D30) -> #REF!
C31: CAPEX/ MCI (원/Km) | D31: Fixed O&M (원/km/yr) | E31: - | F31: - | G31: CAPEX/ MCI (원/Km) | H31: Fixed O&M (원/km/yr) | I31: - | J31: - | K31: CAPEX/ MCI (원/Km) | L31: Fixed O&M (원/km/yr) | M31: - | N31: - | O31: CAPEX/ MCI (원/Km) | P31: Fixed O&M (원/km/yr) | Q31: - | R31: - | S31: CAPEX/ MCI (원/Km) | T31: Fixed O&M (원/km/yr) | U31: - | V31: -
A32: Transmission | B32: Transmission lines 345kV | C32: ='[7]★Cost datasheet_v2'!E32*(1+'[7]★Cost datasheet_v2'!O32)^(2025-'[7]★Cost datasheet_v2'!$D32) -> 7.3231939e+09 | D32: ='[7]★Cost datasheet_v2'!F32*(1+'[7]★Cost datasheet_v2'!P32)^(2025-'[7]★Cost datasheet_v2'!$D32) -> 37402211 | E32: ='[7]★Cost datasheet_v2'!G32*(1+'[7]★Cost datasheet_v2'!Q32)^(2025-'[7]★Cost datasheet_v2'!$D32) -> #REF! | F32: ='[7]★Cost datasheet_v2'!H32*(1+'[7]★Cost datasheet_v2'!R32)^(2025-'[7]★Cost datasheet_v2'!$D32) -> #REF! | G32: ='[7]★Cost datasheet_v2'!E32*(1+'[7]★Cost datasheet_v2'!O32)^(2030-'[7]★Cost datasheet_v2'!$D32) -> 7.3231939e+09 | H32: ='[7]★Cost datasheet_v2'!F32*(1+'[7]★Cost datasheet_v2'!P32)^(2030-'[7]★Cost datasheet_v2'!$D32) -> 37672992 | I32: ='[7]★Cost datasheet_v2'!G32*(1+'[7]★Cost datasheet_v2'!Q32)^(2030-'[7]★Cost datasheet_v2'!$D32) -> #REF! | J32: ='[7]★Cost datasheet_v2'!H32*(1+'[7]★Cost datasheet_v2'!R32)^(2030-'[7]★Cost datasheet_v2'!$D32) -> #REF! | K32: ='[7]★Cost datasheet_v2'!E32*(1+'[7]★Cost datasheet_v2'!O32)^(2038-'[7]★Cost datasheet_v2'!$D32) -> 7.3231939e+09 | L32: ='[7]★Cost datasheet_v2'!F32*(1+'[7]★Cost datasheet_v2'!P32)^(2038-'[7]★Cost datasheet_v2'!$D32) -> 38110324 | M32: ='[7]★Cost datasheet_v2'!G32*(1+'[7]★Cost datasheet_v2'!Q32)^(2038-'[7]★Cost datasheet_v2'!$D32) -> #REF! | N32: ='[7]★Cost datasheet_v2'!H32*(1+'[7]★Cost datasheet_v2'!R32)^(2038-'[7]★Cost datasheet_v2'!$D32) -> #REF! | O32: ='[7]★Cost datasheet_v2'!E32*(1+'[7]★Cost datasheet_v2'!O32)^(2040-'[7]★Cost datasheet_v2'!$D32) -> 7.3231939e+09 | P32: ='[7]★Cost datasheet_v2'!F32*(1+'[7]★Cost datasheet_v2'!P32)^(2040-'[7]★Cost datasheet_v2'!$D32) -> 38220448 | Q32: ='[7]★Cost datasheet_v2'!G32*(1+'[7]★Cost datasheet_v2'!Q32)^(2040-'[7]★Cost datasheet_v2'!$D32) -> #REF! | R32: ='[7]★Cost datasheet_v2'!H32*(1+'[7]★Cost datasheet_v2'!R32)^(2040-'[7]★Cost datasheet_v2'!$D32) -> #REF! | S32: ='[7]★Cost datasheet_v2'!E32*(1+'[7]★Cost datasheet_v2'!O32)^(2050-'[7]★Cost datasheet_v2'!$D32) -> 7.3231939e+09 | T32: ='[7]★Cost datasheet_v2'!F32*(1+'[7]★Cost datasheet_v2'!P32)^(2050-'[7]★Cost datasheet_v2'!$D32) -> 38775861 | U32: ='[7]★Cost datasheet_v2'!G32*(1+'[7]★Cost datasheet_v2'!Q32)^(2050-'[7]★Cost datasheet_v2'!$D32) -> #REF! | V32: ='[7]★Cost datasheet_v2'!H32*(1+'[7]★Cost datasheet_v2'!R32)^(2050-'[7]★Cost datasheet_v2'!$D32) -> #REF!
B33: Transmission lines 500kV | C33: ='[7]★Cost datasheet_v2'!E33*(1+'[7]★Cost datasheet_v2'!O33)^(2025-'[7]★Cost datasheet_v2'!$D33) -> 8.4964047e+09 | D33: ='[7]★Cost datasheet_v2'!F33*(1+'[7]★Cost datasheet_v2'!P33)^(2025-'[7]★Cost datasheet_v2'!$D33) -> 43456876 | E33: ='[7]★Cost datasheet_v2'!G33*(1+'[7]★Cost datasheet_v2'!Q33)^(2025-'[7]★Cost datasheet_v2'!$D33) -> #REF! | F33: ='[7]★Cost datasheet_v2'!H33*(1+'[7]★Cost datasheet_v2'!R33)^(2025-'[7]★Cost datasheet_v2'!$D33) -> #REF! | G33: ='[7]★Cost datasheet_v2'!E33*(1+'[7]★Cost datasheet_v2'!O33)^(2030-'[7]★Cost datasheet_v2'!$D33) -> 8.4964047e+09 | H33: ='[7]★Cost datasheet_v2'!F33*(1+'[7]★Cost datasheet_v2'!P33)^(2030-'[7]★Cost datasheet_v2'!$D33) -> 43771490 | I33: ='[7]★Cost datasheet_v2'!G33*(1+'[7]★Cost datasheet_v2'!Q33)^(2030-'[7]★Cost datasheet_v2'!$D33) -> #REF! | J33: ='[7]★Cost datasheet_v2'!H33*(1+'[7]★Cost datasheet_v2'!R33)^(2030-'[7]★Cost datasheet_v2'!$D33) -> #REF! | K33: ='[7]★Cost datasheet_v2'!E33*(1+'[7]★Cost datasheet_v2'!O33)^(2038-'[7]★Cost datasheet_v2'!$D33) -> 8.4964047e+09 | L33: ='[7]★Cost datasheet_v2'!F33*(1+'[7]★Cost datasheet_v2'!P33)^(2038-'[7]★Cost datasheet_v2'!$D33) -> 44279618 | M33: ='[7]★Cost datasheet_v2'!G33*(1+'[7]★Cost datasheet_v2'!Q33)^(2038-'[7]★Cost datasheet_v2'!$D33) -> #REF! | N33: ='[7]★Cost datasheet_v2'!H33*(1+'[7]★Cost datasheet_v2'!R33)^(2038-'[7]★Cost datasheet_v2'!$D33) -> #REF! | O33: ='[7]★Cost datasheet_v2'!E33*(1+'[7]★Cost datasheet_v2'!O33)^(2040-'[7]★Cost datasheet_v2'!$D33) -> 8.4964047e+09 | P33: ='[7]★Cost datasheet_v2'!F33*(1+'[7]★Cost datasheet_v2'!P33)^(2040-'[7]★Cost datasheet_v2'!$D33) -> 44407569 | Q33: ='[7]★Cost datasheet_v2'!G33*(1+'[7]★Cost datasheet_v2'!Q33)^(2040-'[7]★Cost datasheet_v2'!$D33) -> #REF! | R33: ='[7]★Cost datasheet_v2'!H33*(1+'[7]★Cost datasheet_v2'!R33)^(2040-'[7]★Cost datasheet_v2'!$D33) -> #REF! | S33: ='[7]★Cost datasheet_v2'!E33*(1+'[7]★Cost datasheet_v2'!O33)^(2050-'[7]★Cost datasheet_v2'!$D33) -> 8.4964047e+09 | T33: ='[7]★Cost datasheet_v2'!F33*(1+'[7]★Cost datasheet_v2'!P33)^(2050-'[7]★Cost datasheet_v2'!$D33) -> 45052891 | U33: ='[7]★Cost datasheet_v2'!G33*(1+'[7]★Cost datasheet_v2'!Q33)^(2050-'[7]★Cost datasheet_v2'!$D33) -> #REF! | V33: ='[7]★Cost datasheet_v2'!H33*(1+'[7]★Cost datasheet_v2'!R33)^(2050-'[7]★Cost datasheet_v2'!$D33) -> #REF!
B34: Transmission lines 765kV | C34: ='[7]★Cost datasheet_v2'!E34*(1+'[7]★Cost datasheet_v2'!O34)^(2025-'[7]★Cost datasheet_v2'!$D34) -> 7.6732673e+09 | D34: ='[7]★Cost datasheet_v2'!F34*(1+'[7]★Cost datasheet_v2'!P34)^(2025-'[7]★Cost datasheet_v2'!$D34) -> 39190163 | E34: ='[7]★Cost datasheet_v2'!G34*(1+'[7]★Cost datasheet_v2'!Q34)^(2025-'[7]★Cost datasheet_v2'!$D34) -> #REF! | F34: ='[7]★Cost datasheet_v2'!H34*(1+'[7]★Cost datasheet_v2'!R34)^(2025-'[7]★Cost datasheet_v2'!$D34) -> #REF! | G34: ='[7]★Cost datasheet_v2'!E34*(1+'[7]★Cost datasheet_v2'!O34)^(2030-'[7]★Cost datasheet_v2'!$D34) -> 7.6732673e+09 | H34: ='[7]★Cost datasheet_v2'!F34*(1+'[7]★Cost datasheet_v2'!P34)^(2030-'[7]★Cost datasheet_v2'!$D34) -> 39473888 | I34: ='[7]★Cost datasheet_v2'!G34*(1+'[7]★Cost datasheet_v2'!Q34)^(2030-'[7]★Cost datasheet_v2'!$D34) -> #REF! | J34: ='[7]★Cost datasheet_v2'!H34*(1+'[7]★Cost datasheet_v2'!R34)^(2030-'[7]★Cost datasheet_v2'!$D34) -> #REF! | K34: ='[7]★Cost datasheet_v2'!E34*(1+'[7]★Cost datasheet_v2'!O34)^(2038-'[7]★Cost datasheet_v2'!$D34) -> 7.6732673e+09 | L34: ='[7]★Cost datasheet_v2'!F34*(1+'[7]★Cost datasheet_v2'!P34)^(2038-'[7]★Cost datasheet_v2'!$D34) -> 39932127 | M34: ='[7]★Cost datasheet_v2'!G34*(1+'[7]★Cost datasheet_v2'!Q34)^(2038-'[7]★Cost datasheet_v2'!$D34) -> #REF! | N34: ='[7]★Cost datasheet_v2'!H34*(1+'[7]★Cost datasheet_v2'!R34)^(2038-'[7]★Cost datasheet_v2'!$D34) -> #REF! | O34: ='[7]★Cost datasheet_v2'!E34*(1+'[7]★Cost datasheet_v2'!O34)^(2040-'[7]★Cost datasheet_v2'!$D34) -> 7.6732673e+09 | P34: ='[7]★Cost datasheet_v2'!F34*(1+'[7]★Cost datasheet_v2'!P34)^(2040-'[7]★Cost datasheet_v2'!$D34) -> 40047515 | Q34: ='[7]★Cost datasheet_v2'!G34*(1+'[7]★Cost datasheet_v2'!Q34)^(2040-'[7]★Cost datasheet_v2'!$D34) -> #REF! | R34: ='[7]★Cost datasheet_v2'!H34*(1+'[7]★Cost datasheet_v2'!R34)^(2040-'[7]★Cost datasheet_v2'!$D34) -> #REF! | S34: ='[7]★Cost datasheet_v2'!E34*(1+'[7]★Cost datasheet_v2'!O34)^(2050-'[7]★Cost datasheet_v2'!$D34) -> 7.6732673e+09 | T34: ='[7]★Cost datasheet_v2'!F34*(1+'[7]★Cost datasheet_v2'!P34)^(2050-'[7]★Cost datasheet_v2'!$D34) -> 40629478 | U34: ='[7]★Cost datasheet_v2'!G34*(1+'[7]★Cost datasheet_v2'!Q34)^(2050-'[7]★Cost datasheet_v2'!$D34) -> #REF! | V34: ='[7]★Cost datasheet_v2'!H34*(1+'[7]★Cost datasheet_v2'!R34)^(2050-'[7]★Cost datasheet_v2'!$D34) -> #REF!
A37: 할인율 | C37: 설비비용 | D37: 한계비용 | G37: cap | J37: marginal
A38: 0.05 | G38: 2024 | H38: 2030 | I38: 2038
F39: PV | G39: 1 | H39: =G6/C6 -> 0.86762354
F40: WT | G40: 1 | H40: =G8/C8 -> 0.9131822
F41: LNG | G41: 1 | H41: =G15/C15 -> 1.0836673
F42: COAL | G42: 1 | H42: =G14/C14 -> 1.0836673
F43: NUCLEAR | G43: 1 | H43: =G16/C16 -> 1.1341704
F44: HYDRO | G44: 1
...

Sheet 개발노트
B2: 중앙발전기의 출력특성 반영 | C2: unit commitment
B3: 재생에너지 발전의 curtailment 규칙 반영 | C3: 재생에너지 버스 구축 curtailment storage로 구성
A6: 45930 | B6: 배출량 제약 구현 | C6: 배출량 제약 구현을 위해서 CHP 발전의 배출량 계산 처리 - 전력과 열의 생산효율 비중에 따라 전력 생산 배출량, 열 생산 배출량으로 구분
B8: 지역별 재생에너지 의무비중 설정
